<?xml version="1.0"?>
<robot name="ex_urdf_pan_tilt">

    <link name="base_link">
        <visual>
            <geometry>
                <cylinder length="0.01" radius="0.2"/>
            </geometry>
            <origin rpy="0 0 0" xyz="0 0 0"/>
            <material name="yellow">
                <color rgba="1 1 0 1"/>
            </material>
        </visual>

        <collision>
            <geometry>
                <cylinder length="0.03" radius="0.2"/>
            </geometry>
            <origin rpy="0 0 0" xyz="0 0 0"/>
        </collision>

        <inertial>
            <mass value="1"/>
            <inertia ixx="1.0" ixy="0.0" ixz="0.0" iyy="1.0" iyz="0.0" izz="1.0"/>
        </inertial>
    </link>

    <joint name="pan_joint" type="revolute">
        <parent link="base_link"/>
        <child link="pan_link"/>
        <origin xyz="0 0 0.1"/>
        <axis xyz="0 0 1" />
        <limit effort="300" velocity="0.1" lower="-3.14" upper="3.14"/>
        <dynamics damping="50" friction="1"/>
    </joint>

    <link name="pan_link">
        <visual>
            <geometry>
                <cylinder length="0.4" radius="0.04"/>
            </geometry>
            <origin rpy="0 0 0" xyz="0 0 0.09"/>
            <material name="red">
                <color rgba="0 0 1 1"/>
            </material>
        </visual>

        <collision>
            <geometry>
                <cylinder length="0.4" radius="0.06"/>
            </geometry>
            <origin rpy="0 0 0" xyz="0 0 0.09"/>
        </collision>

        <inertial>
            <mass value="1"/>
            <inertia ixx="1.0" ixy="0.0" ixz="0.0" iyy="1.0" iyz="0.0" izz="1.0"/>
        </inertial>
    </link>

    <joint name="tilt_joint" type="revolute">
        <parent link="pan_link"/>
        <child link="tilt_link"/>
        <origin xyz="0 0 0.2"/>
        <axis xyz="0 1 0" />
        <limit effort="300" velocity="0.1" lower="-4.71239" upper="-1.570796"/>
        <dynamics damping="50" friction="1"/>
    </joint>

    <link name="tilt_link">
        <visual>
            <geometry>
                <cylinder length="0.4" radius="0.04"/>
            </geometry>
            <origin rpy="0 1.570796 0" xyz="0 0 0"/>
            <material name="green">
                <color rgba="1 0 0 1"/>
            </material>
        </visual>

        <collision>
            <geometry>
                <cylinder length="0.4" radius="0.06"/>
            </geometry>
            <origin rpy="0 1.570796 0" xyz="0 0 0"/>
        </collision>

        <inertial>
            <mass value="1"/>
            <inertia ixx="1.0" ixy="0.0" ixz="0.0" iyy="1.0" iyz="0.0" izz="1.0"/>
        </inertial>
    </link>

	<sensor type="camera" name="camera1">
      <update_rate>30.0</update_rate>
      <camera name="head">
        <horizontal_fov>1.3962634</horizontal_fov>
        <image>
          <width>800</width>
          <height>800</height>
          <format>R8G8B8</format>
        </image>
        <clip>
          <near>0.02</near>
          <far>300</far>
        </clip>
        <noise>
          <type>gaussian</type>
          <!-- Noise is sampled independently per pixel on each frame.
               That pixel's noise value is added to each of its color
               channels, which at that point lie in the range [0,1]. -->
          <mean>0.0</mean>
          <stddev>0.007</stddev>
        </noise>
      </camera>
      <plugin name="camera_controller" filename="libgazebo_ros_camera.so">
        <alwaysOn>true</alwaysOn>
        <updateRate>0.0</updateRate>
        <cameraName>rrbot/camera1</cameraName>
        <imageTopicName>image_raw</imageTopicName>
        <cameraInfoTopicName>camera_info</cameraInfoTopicName>
        <frameName>camera_link</frameName>
        <hackBaseline>0.07</hackBaseline>
        <distortionK1>0.0</distortionK1>
        <distortionK2>0.0</distortionK2>
        <distortionK3>0.0</distortionK3>
        <distortionT1>0.0</distortionT1>
        <distortionT2>0.0</distortionT2>
      </plugin>
    </sensor>
    
    
</robot>
